Workbook

Sheet Instructions
B2: CyberArk PAM – On-Prem to Modern PAM (SaaS) Migration
B3: Total Cost of Ownership (TCO) & ROI Model · 3-Year Horizon · EUR
B5: Purpose | C5: Compares the fully-loaded 3-year cost of keeping CyberArk PAM self-hosted (on-premises) against migrating to CyberArk's SaaS offering (Privilege Cloud / Modern PAM). Produces net savings, ROI% and payback period to support the migration business case.
B6: How to use | C6: Go to the 'Inputs & Assumptions' tab and edit the coloured cells. Everything else calculates automatically. The two most important numbers are your actual annual on-prem renewal cost and the annual SaaS subscription quote – replace the example values in the yellow cells first.
B8: Cell colour legend
B9: Yellow fill | C9: Key figures you MUST provide (renewal cost, SaaS quote, component counts).
B10: Blue text | C10: Editable inputs / assumptions pre-filled with industry defaults – override as needed.
B11: Black text | C11: Calculated formulas – do not overwrite.
B12: Green text | C12: Value pulled from another sheet.
B14: Tabs | C14: Inputs & Assumptions – every lever in one place. On-Prem TCO – infrastructure + operations + licence build-up for the self-hosted estate. SaaS TCO – subscription + residual connectors + migration. ROI Summary – side-by-side comparison, savings, payback and charts.
B15: Scope assumption | C15: SaaS residual infrastructure is modelled as 'minimal / CyberArk-hosted' – only a pair of lightweight connector VMs remain on-prem. Platform patching, upgrades, HA/DR and backup of the Vault estate move to CyberArk and drop out of the customer's cost base.
B16: Disclaimer | C16: Default unit rates (compute, storage, OS, labour, upgrade effort) are illustrative industry benchmarks, not a quote. Replace with the customer's real figures before presenting. Licence/subscription prices are entered by the user and are not sourced from CyberArk price lists.

Sheet ROI Summary
B2: ROI & TCO SUMMARY – 3-Year
B4: Headline results
B5: 3-Year Net Savings | C5: 3-Year ROI | D5: Payback Period | E5: Annual Run-Rate Saving
B6: ='On-Prem TCO'!$F$29-'SaaS TCO'!$F$18 -> 515593 | C6: =('On-Prem TCO'!$F$29-'SaaS TCO'!$F$18)/'SaaS TCO'!$F$18 -> 0.78177126 | D6: =IF(('On-Prem TCO'!$D$29-'SaaS TCO'!$D$18)<=0,0,'SaaS TCO'!$C$17/('On-Prem TCO'!$D$29-'SaaS TCO'!$D$18)*12) -> 4.3597065 | E6: ='On-Prem TCO'!$D$29-'SaaS TCO'!$D$18 -> 195426
B8: 3-Year TCO comparison by category
B9: Cost category | C9: On-Prem (3yr) | D9: SaaS (3yr) | E9: Saving | I9: Category | J9: On-Prem | K9: SaaS
B10: Licence / Subscription | C10: ='On-Prem TCO'!$F$25 -> 567450 | D10: ='SaaS TCO'!$F$14 -> 463635 | E10: =C10-D10 -> 103815 | I10: Licence/Sub | J10: =C10 -> 567450 | K10: =D10 -> 463635
B11: Infrastructure | C11: ='On-Prem TCO'!$F$26 -> 96162 | D11: ='SaaS TCO'!$F$15 -> 10884 | E11: =C11-D11 -> 85278 | I11: Infrastructure | J11: =C11 -> 96162 | K11: =D11 -> 10884
B12: Operations & labour | C12: ='On-Prem TCO'!$F$27 -> 451500 | D12: ='SaaS TCO'!$F$16 -> 114000 | E12: =C12-D12 -> 337500 | I12: Operations | J12: =C12 -> 451500 | K12: =D12 -> 114000
B13: Version upgrades | C13: ='On-Prem TCO'!$F$28 -> 60000 | D13: =0 -> 0 | E13: =C13-D13 -> 60000 | I13: Upgrades | J13: =C13 -> 60000 | K13: =D13 -> 0
B14: One-time migration | C14: =0 -> 0 | D14: ='SaaS TCO'!$F$17 -> 71000 | E14: =C14-D14 -> -71000 | I14: Migration | J14: =C14 -> 0 | K14: =D14 -> 71000
B15: TOTAL | C15: =SUM(C10:C14) -> 1175112 | D15: =SUM(D10:D14) -> 659519 | E15: =SUM(E10:E14) -> 515593
B17: Annual cash flow & cumulative savings
C18: Year 1 | D18: Year 2 | E18: Year 3 | M18: Year | N18: On-Prem cum | O18: SaaS cum
B19: On-Prem annual cost | C19: ='On-Prem TCO'!$C$29 -> 382554 | D19: ='On-Prem TCO'!$D$29 -> 391554 | E19: ='On-Prem TCO'!$E$29 -> 401004 | M19: Year 1 | N19: =C19 -> 382554 | O19: =C20 -> 262628
B20: SaaS annual cost (incl. migration Y1) | C20: ='SaaS TCO'!$C$18 -> 262628 | D20: ='SaaS TCO'!$D$18 -> 196128 | E20: ='SaaS TCO'!$E$18 -> 200763 | M20: Year 2 | N20: =N19+D19 -> 774108 | O20: =O19+D20 -> 458756
B21: Annual saving | C21: =C19-C20 -> 119926 | D21: =D19-D20 -> 195426 | E21: =E19-E20 -> 200241 | M21: Year 3 | N21: =N20+E19 -> 1175112 | O21: =O20+E20 -> 659519
B22: Cumulative saving | C22: =C21 -> 119926 | D22: =C22+D21 -> 315352 | E22: =D22+E21 -> 515593
B24: NPV of 3-yr savings (at discount rate) | C24: =NPV('Inputs & Assumptions'!$C$51,C21:E21) -> 437546.65

Sheet Inputs & Assumptions
B2: INPUTS & ASSUMPTIONS
B4: A. Licensing / Subscription (enter your real figures)
B5: On-prem annual licence renewal (maintenance) | C5: 180000 | I5: ← your actual renewal quote
B6: On-prem renewal annual uplift % | C6: 0.05
B7: SaaS annual subscription (Privilege Cloud) | C7: 150000 | I7: ← your SaaS quote (annual)
B8: SaaS subscription annual uplift % | C8: 0.03
B10: B. On-Prem Component Inventory & Sizing (set the quantities)
B11: Component | C11: Qty | D11: vCPU each | E11: RAM GB each | F11: Storage GB each | G11: OS | H11: Role
B12: Vault (Primary Cluster) | C12: 2 | D12: 8 | E12: 32 | F12: 500 | G12: Windows | H12: Digital Vault
B13: Vault DR | C13: 1 | D13: 8 | E13: 32 | F13: 500 | G13: Windows | H13: Disaster Recovery
B14: CPM | C14: 2 | D14: 4 | E14: 8 | F14: 100 | G14: Windows | H14: Central Policy Manager
B15: PSM | C15: 3 | D15: 8 | E15: 16 | F15: 250 | G15: Windows | H15: Privileged Session Mgr
B16: PSMP | C16: 2 | D16: 4 | E16: 8 | F16: 100 | G16: Linux | H16: PSM for SSH
B17: PTA | C17: 1 | D17: 8 | E17: 32 | F17: 1000 | G17: Linux | H17: Threat Analytics
B19: C. Infrastructure Unit Rates (annual, EUR – industry defaults)
B20: Compute – per vCPU / year | C20: 120 | I20: virtualised, incl. hypervisor
B21: Compute – per GB RAM / year | C21: 18
B22: Storage – per GB / year | C22: 0.6 | I22: enterprise SAN + snapshots
B23: Windows Server licence / VM / year | C23: 350 | I23: amortised incl. SA
B24: Linux (RHEL) subscription / VM / year | C24: 700
B25: Backup / VM / year | C25: 180
B26: Facilities (power, cooling, DC space) / VM / year | C26: 600
B27: Network / load-balancer / firewall allocation / year | C27: 4000 | I27: environment-level, once
B28: HSM / key management / year (0 if none) | C28: 0
B30: D. Operations & Labour
B31: Fully-loaded FTE cost / year | C31: 95000 | I31: salary + overhead
B32: On-prem PAM platform + infra admin (FTE) | C32: 1.5 | I32: patching, upgrades, HA/DR, backup
B33: SaaS PAM admin (FTE) | C33: 0.4 | I33: policy admin only
B34: Major version upgrade – cost each | C34: 30000 | I34: services + internal effort
B35: Number of major upgrades in horizon | C35: 2 | I35: on-prem only
B36: DR test / audit / year | C36: 8000
B38: E. One-Time Migration Cost (SaaS project, Year 1)
B39: Professional services (migration) | C39: 45000 | I39: CyberArk / partner
B40: Internal migration effort | C40: 20000
B41: Training & enablement | C41: 6000
B43: F. SaaS Residual On-Prem Connectors (minimal footprint)
B44: Connector VMs remaining on-prem (Qty) | C44: 2
B45: vCPU each | C45: 4
B46: RAM GB each | C46: 8
B47: Storage GB each | C47: 100
...

Sheet On-Prem TCO
B2: ON-PREM (SELF-HOSTED) TCO
B4: 1. Infrastructure – annual cost build-up per component
B5: Component | C5: Qty | D5: Tot vCPU | E5: Tot RAM | F5: Tot Stor | G5: Compute € | H5: Storage € | I5: OS € | J5: Backup € | K5: Facilities € | L5: Annual €
B6: ='Inputs & Assumptions'!B12 -> Vault (Primary Cluster) | C6: ='Inputs & Assumptions'!C12 -> 2 | D6: ='Inputs & Assumptions'!C12*'Inputs & Assumptions'!D12 -> 16 | E6: ='Inputs & Assumptions'!C12*'Inputs & Assumptions'!E12 -> 64 | F6: ='Inputs & Assumptions'!C12*'Inputs & Assumptions'!F12 -> 1000 | G6: =D6*'Inputs & Assumptions'!$C$20+E6*'Inputs & Assumptions'!$C$21 -> 3072 | H6: =F6*'Inputs & Assumptions'!$C$22 -> 600 | I6: =C6*IF('Inputs & Assumptions'!G12="Windows",'Inputs & Assumptions'!$C$23,'Inputs & Assumptions'!$C$24) -> 700 | J6: =C6*'Inputs & Assumptions'!$C$25 -> 360 | K6: =C6*'Inputs & Assumptions'!$C$26 -> 1200 | L6: =SUM(G6:K6) -> 5932
B7: ='Inputs & Assumptions'!B13 -> Vault DR | C7: ='Inputs & Assumptions'!C13 -> 1 | D7: ='Inputs & Assumptions'!C13*'Inputs & Assumptions'!D13 -> 8 | E7: ='Inputs & Assumptions'!C13*'Inputs & Assumptions'!E13 -> 32 | F7: ='Inputs & Assumptions'!C13*'Inputs & Assumptions'!F13 -> 500 | G7: =D7*'Inputs & Assumptions'!$C$20+E7*'Inputs & Assumptions'!$C$21 -> 1536 | H7: =F7*'Inputs & Assumptions'!$C$22 -> 300 | I7: =C7*IF('Inputs & Assumptions'!G13="Windows",'Inputs & Assumptions'!$C$23,'Inputs & Assumptions'!$C$24) -> 350 | J7: =C7*'Inputs & Assumptions'!$C$25 -> 180 | K7: =C7*'Inputs & Assumptions'!$C$26 -> 600 | L7: =SUM(G7:K7) -> 2966
B8: ='Inputs & Assumptions'!B14 -> CPM | C8: ='Inputs & Assumptions'!C14 -> 2 | D8: ='Inputs & Assumptions'!C14*'Inputs & Assumptions'!D14 -> 8 | E8: ='Inputs & Assumptions'!C14*'Inputs & Assumptions'!E14 -> 16 | F8: ='Inputs & Assumptions'!C14*'Inputs & Assumptions'!F14 -> 200 | G8: =D8*'Inputs & Assumptions'!$C$20+E8*'Inputs & Assumptions'!$C$21 -> 1248 | H8: =F8*'Inputs & Assumptions'!$C$22 -> 120 | I8: =C8*IF('Inputs & Assumptions'!G14="Windows",'Inputs & Assumptions'!$C$23,'Inputs & Assumptions'!$C$24) -> 700 | J8: =C8*'Inputs & Assumptions'!$C$25 -> 360 | K8: =C8*'Inputs & Assumptions'!$C$26 -> 1200 | L8: =SUM(G8:K8) -> 3628
B9: ='Inputs & Assumptions'!B15 -> PSM | C9: ='Inputs & Assumptions'!C15 -> 3 | D9: ='Inputs & Assumptions'!C15*'Inputs & Assumptions'!D15 -> 24 | E9: ='Inputs & Assumptions'!C15*'Inputs & Assumptions'!E15 -> 48 | F9: ='Inputs & Assumptions'!C15*'Inputs & Assumptions'!F15 -> 750 | G9: =D9*'Inputs & Assumptions'!$C$20+E9*'Inputs & Assumptions'!$C$21 -> 3744 | H9: =F9*'Inputs & Assumptions'!$C$22 -> 450 | I9: =C9*IF('Inputs & Assumptions'!G15="Windows",'Inputs & Assumptions'!$C$23,'Inputs & Assumptions'!$C$24) -> 1050 | J9: =C9*'Inputs & Assumptions'!$C$25 -> 540 | K9: =C9*'Inputs & Assumptions'!$C$26 -> 1800 | L9: =SUM(G9:K9) -> 7584
B10: ='Inputs & Assumptions'!B16 -> PSMP | C10: ='Inputs & Assumptions'!C16 -> 2 | D10: ='Inputs & Assumptions'!C16*'Inputs & Assumptions'!D16 -> 8 | E10: ='Inputs & Assumptions'!C16*'Inputs & Assumptions'!E16 -> 16 | F10: ='Inputs & Assumptions'!C16*'Inputs & Assumptions'!F16 -> 200 | G10: =D10*'Inputs & Assumptions'!$C$20+E10*'Inputs & Assumptions'!$C$21 -> 1248 | H10: =F10*'Inputs & Assumptions'!$C$22 -> 120 | I10: =C10*IF('Inputs & Assumptions'!G16="Windows",'Inputs & Assumptions'!$C$23,'Inputs & Assumptions'!$C$24) -> 1400 | J10: =C10*'Inputs & Assumptions'!$C$25 -> 360 | K10: =C10*'Inputs & Assumptions'!$C$26 -> 1200 | L10: =SUM(G10:K10) -> 4328
B11: ='Inputs & Assumptions'!B17 -> PTA | C11: ='Inputs & Assumptions'!C17 -> 1 | D11: ='Inputs & Assumptions'!C17*'Inputs & Assumptions'!D17 -> 8 | E11: ='Inputs & Assumptions'!C17*'Inputs & Assumptions'!E17 -> 32 | F11: ='Inputs & Assumptions'!C17*'Inputs & Assumptions'!F17 -> 1000 | G11: =D11*'Inputs & Assumptions'!$C$20+E11*'Inputs & Assumptions'!$C$21 -> 1536 | H11: =F11*'Inputs & Assumptions'!$C$22 -> 600 | I11: =C11*IF('Inputs & Assumptions'!G17="Windows",'Inputs & Assumptions'!$C$23,'Inputs & Assumptions'!$C$24) -> 700 | J11: =C11*'Inputs & Assumptions'!$C$25 -> 180 | K11: =C11*'Inputs & Assumptions'!$C$26 -> 600 | L11: =SUM(G11:K11) -> 3616
B12: Subtotal – servers | C12: =SUM(C6:C11) -> 11 | D12: =SUM(D6:D11) -> 72 | E12: =SUM(E6:E11) -> 208 | F12: =SUM(F6:F11) -> 3650 | G12: =SUM(G6:G11) -> 12384 | H12: =SUM(H6:H11) -> 2190 | I12: =SUM(I6:I11) -> 4900 | J12: =SUM(J6:J11) -> 1980 | ... L12: =SUM(L6:L11) -> 28054
B13: Network / LB / firewall (environment) | L13: ='Inputs & Assumptions'!$C$27 -> 4000
B14: HSM / key management | L14: ='Inputs & Assumptions'!$C$28 -> 0
B15: Infrastructure – total annual | L15: =L12+L13+L14 -> 32054
B17: 2. Operations – annual
B18: Item | K18: Basis | L18: Annual €
B19: Platform + infrastructure administration | K19: ='Inputs & Assumptions'!C32 & " FTE" -> 1.5 FTE | L19: ='Inputs & Assumptions'!$C$32*'Inputs & Assumptions'!$C$31 -> 142500
B20: DR test / audit | L20: ='Inputs & Assumptions'!$C$36 -> 8000
B21: Operations – total annual | L21: =L19+L20 -> 150500
B23: 3. 3-Year TCO build
B24: Cost line | C24: Year 1 | D24: Year 2 | E24: Year 3 | F24: 3-Year Total
B25: Software licence / maintenance | C25: ='Inputs & Assumptions'!$C$5 -> 180000 | D25: =C25*(1+'Inputs & Assumptions'!$C$6) -> 189000 | E25: =D25*(1+'Inputs & Assumptions'!$C$6) -> 198450 | F25: =SUM(C25:E25) -> 567450
B26: Infrastructure | C26: ='On-Prem TCO'!$L$15 -> 32054 | D26: ='On-Prem TCO'!$L$15 -> 32054 | E26: ='On-Prem TCO'!$L$15 -> 32054 | F26: =SUM(C26:E26) -> 96162
B27: Operations & labour | C27: ='On-Prem TCO'!$L$21 -> 150500 | D27: ='On-Prem TCO'!$L$21 -> 150500 | E27: ='On-Prem TCO'!$L$21 -> 150500 | F27: =SUM(C27:E27) -> 451500
B28: Major version upgrades (annualised) | C28: ='Inputs & Assumptions'!$C$34*'Inputs & Assumptions'!$C$35/'Inputs & Assumptions'!$C$50 -> 20000 | D28: ='Inputs & Assumptions'!$C$34*'Inputs & Assumptions'!$C$35/'Inputs & Assumptions'!$C$50 -> 20000 | E28: ='Inputs & Assumptions'!$C$34*'Inputs & Assumptions'!$C$35/'Inputs & Assumptions'!$C$50 -> 20000 | F28: =SUM(C28:E28) -> 60000
B29: TOTAL On-Prem TCO | C29: =SUM(C25:C28) -> 382554 | D29: =SUM(D25:D28) -> 391554 | E29: =SUM(E25:E28) -> 401004 | F29: =SUM(F25:F28) -> 1175112

Sheet SaaS TCO
B2: CYBERARK MODERN PAM (SaaS) TCO
B4: 1. Residual on-prem connector infrastructure – annual
B5: Item | F5: Annual €
B6: Compute (vCPU + RAM) | F6: ='Inputs & Assumptions'!$C$44*'Inputs & Assumptions'!$C$45*'Inputs & Assumptions'!$C$20+'Inputs & Assumptions'!$C$44*'Inputs & Assumptions'!$C$46*'Inputs & Assumptions'!$C$21 -> 1248
B7: Storage | F7: ='Inputs & Assumptions'!$C$44*'Inputs & Assumptions'!$C$47*'Inputs & Assumptions'!$C$22 -> 120
B8: OS licence (Windows) | F8: ='Inputs & Assumptions'!$C$44*'Inputs & Assumptions'!$C$23 -> 700
B9: Backup + facilities | F9: ='Inputs & Assumptions'!$C$44*('Inputs & Assumptions'!$C$25+'Inputs & Assumptions'!$C$26) -> 1560
B10: Connector infra – total annual | F10: =SUM(F6:F9) -> 3628
B12: 2. 3-Year TCO build
B13: Cost line | C13: Year 1 | D13: Year 2 | E13: Year 3 | F13: 3-Year Total
B14: SaaS subscription | C14: ='Inputs & Assumptions'!$C$7 -> 150000 | D14: =C14*(1+'Inputs & Assumptions'!$C$8) -> 154500 | E14: =D14*(1+'Inputs & Assumptions'!$C$8) -> 159135 | F14: =SUM(C14:E14) -> 463635
B15: Residual connector infrastructure | C15: ='SaaS TCO'!$F$10 -> 3628 | D15: ='SaaS TCO'!$F$10 -> 3628 | E15: ='SaaS TCO'!$F$10 -> 3628 | F15: =SUM(C15:E15) -> 10884
B16: Operations & labour (policy admin) | C16: ='Inputs & Assumptions'!$C$33*'Inputs & Assumptions'!$C$31 -> 38000 | D16: ='Inputs & Assumptions'!$C$33*'Inputs & Assumptions'!$C$31 -> 38000 | E16: ='Inputs & Assumptions'!$C$33*'Inputs & Assumptions'!$C$31 -> 38000 | F16: =SUM(C16:E16) -> 114000
B17: One-time migration (Year 1) | C17: ='Inputs & Assumptions'!$C$39+'Inputs & Assumptions'!$C$40+'Inputs & Assumptions'!$C$41 -> 71000 | D17: 0 | E17: 0 | F17: =SUM(C17:E17) -> 71000
B18: TOTAL SaaS TCO | C18: =SUM(C14:C17) -> 262628 | D18: =SUM(D14:D17) -> 196128 | E18: =SUM(E14:E17) -> 200763 | F18: =SUM(F14:F17) -> 659519
